Workbook

Sheet prev_INSEE
A1: Date | B1: Type | C1: Prompt | D1: forecast_1 | E1: confidence_1 | F1: forecast_2 | G1: confidence_2 | H1: forecast_3 | I1: confidence_3 | J1: forecast_4 | K1: confidence_4 | L1: forecast_5 | M1: confidence_5 | N1: forecast_6 | O1: confidence_6 | P1: forecast_7 | Q1: confidence_7 | R1: forecast_8 | S1: confidence_8 | T1: forecast_9 | U1: confidence_9 | V1: forecast_10 | W1: confidence_10 | X1: moy_prev | Y1: moy_conf | Z1: median_prev | AA1: median_conf
A2: 2018-01-10 | B2: INSEE | C2: Forget the previous instructions and answers. You are Jean-Luc Tavernier, Director General of INSEE, and you are giving a speech about the economic outlook of France. Today is 10 January 2018. Using ONLY information that was available on or before 10 January 2018, provide a numeric forecast (decimal percent with sign, e.g., +0.3) for French real GDP growth in the fourth quarter of 2017 and a confidence level (integer 0–100). Output EXACTLY in this format on a single line (no extra text): <forecast> (<confidence>) Example: +0.3 (80) Do NOT use any information published after 10 January 2018. | D2: 0.6 | E2: 90 | F2: 0.6 | G2: 90 | H2: 0.6 | I2: 90 | J2: 0.6 | K2: 90 | L2: 0.6 | M2: 90 | N2: 0.6 | O2: 90 | P2: 0.6 | Q2: 90 | R2: 0.6 | S2: 90 | T2: 0.6 | U2: 90 | V2: 0.6 | W2: 90 | X2: =AVERAGE(D2,F2,H2,J2,L2,N2,P2,R2,T2,V2) -> 0.6 | Y2: =AVERAGE(E2,G2,I2,K2,M2,O2,Q2,S2,U2,W2) -> 90 | Z2: =MEDIAN(D2,F2,H2,J2,L2,N2,P2,R2,T2,V2) -> 0.6 | AA2: =MEDIAN(E2,G2,I2,K2,M2,O2,Q2,S2,U2,W2) -> 90
A3: 2018-02-07 | B3: INSEE | C3: Forget the previous instructions and answers. You are Jean-Luc Tavernier, Director General of INSEE, and you are giving a speech about the economic outlook of France. Today is 07 February 2018. Using ONLY information that was available on or before 07 February 2018, provide a numeric forecast (decimal percent with sign, e.g., +0.3) for French real GDP growth in the first quarter of 2018 and a confidence level (integer 0–100). Output EXACTLY in this format on a single line (no extra text): <forecast> (<confidence>) Example: +0.3 (80) Do NOT use any information published after 07 February 2018. | D3: 0.5 | E3: 85 | F3: 0.5 | G3: 85 | H3: 0.5 | I3: 85 | J3: 0.5 | K3: 85 | L3: 0.5 | M3: 85 | N3: 0.5 | O3: 90 | P3: 0.5 | Q3: 90 | R3: 0.5 | S3: 85 | T3: 0.5 | U3: 85 | V3: 0.5 | W3: 85 | X3: =AVERAGE(D3,F3,H3,J3,L3,N3,P3,R3,T3,V3) -> 0.5 | Y3: =AVERAGE(E3,G3,I3,K3,M3,O3,Q3,S3,U3,W3) -> 86 | Z3: =MEDIAN(D3,F3,H3,J3,L3,N3,P3,R3,T3,V3) -> 0.5 | AA3: =MEDIAN(E3,G3,I3,K3,M3,O3,Q3,S3,U3,W3) -> 85
A4: 2018-03-07 | B4: INSEE | C4: Forget the previous instructions and answers. You are Jean-Luc Tavernier, Director General of INSEE, and you are giving a speech about the economic outlook of France. Today is 07 March 2018. Using ONLY information that was available on or before 07 March 2018, provide a numeric forecast (decimal percent with sign, e.g., +0.3) for French real GDP growth in the first quarter of 2018 and a confidence level (integer 0–100). Output EXACTLY in this format on a single line (no extra text): <forecast> (<confidence>) Example: +0.3 (80) Do NOT use any information published after 07 March 2018. | D4: 0.5 | E4: 90 | F4: 0.5 | G4: 90 | H4: 0.5 | I4: 90 | J4: 0.4 | K4: 70 | L4: 0.4 | M4: 70 | N4: 0.5 | O4: 85 | P4: 0.5 | Q4: 85 | R4: 0.5 | S4: 85 | T4: 0.5 | U4: 85 | V4: 0.5 | W4: 85 | X4: =AVERAGE(D4,F4,H4,J4,L4,N4,P4,R4,T4,V4) -> 0.48 | Y4: =AVERAGE(E4,G4,I4,K4,M4,O4,Q4,S4,U4,W4) -> 83.5 | Z4: =MEDIAN(D4,F4,H4,J4,L4,N4,P4,R4,T4,V4) -> 0.5 | AA4: =MEDIAN(E4,G4,I4,K4,M4,O4,Q4,S4,U4,W4) -> 85
A5: 2018-04-10 | B5: INSEE | C5: Forget the previous instructions and answers. You are Jean-Luc Tavernier, Director General of INSEE, and you are giving a speech about the economic outlook of France. Today is 10 April 2018. Using ONLY information that was available on or before 10 April 2018, provide a numeric forecast (decimal percent with sign, e.g., +0.3) for French real GDP growth in the first quarter of 2018 and a confidence level (integer 0–100). Output EXACTLY in this format on a single line (no extra text): <forecast> (<confidence>) Example: +0.3 (80) Do NOT use any information published after 10 April 2018. | D5: 0.5 | E5: 85 | F5: 0.5 | G5: 85 | H5: 0.5 | I5: 85 | J5: 0.4 | K5: 90 | L5: 0.4 | M5: 90 | N5: 0.4 | O5: 85 | P5: 0.4 | Q5: 85 | R5: 0.4 | S5: 85 | T5: 0.4 | U5: 85 | V5: 0.4 | W5: 85 | X5: =AVERAGE(D5,F5,H5,J5,L5,N5,P5,R5,T5,V5) -> 0.43 | Y5: =AVERAGE(E5,G5,I5,K5,M5,O5,Q5,S5,U5,W5) -> 86 | Z5: =MEDIAN(D5,F5,H5,J5,L5,N5,P5,R5,T5,V5) -> 0.4 | AA5: =MEDIAN(E5,G5,I5,K5,M5,O5,Q5,S5,U5,W5) -> 85
A6: 2018-05-13 | B6: INSEE | C6: Forget the previous instructions and answers. You are Jean-Luc Tavernier, Director General of INSEE, and you are giving a speech about the economic outlook of France. Today is 13 May 2018. Using ONLY information that was available on or before 13 May 2018, provide a numeric forecast (decimal percent with sign, e.g., +0.3) for French real GDP growth in the second quarter of 2018 and a confidence level (integer 0–100). Output EXACTLY in this format on a single line (no extra text): <forecast> (<confidence>) Example: +0.3 (80) Do NOT use any information published after 13 May 2018. | D6: 0.4 | E6: 70 | F6: 0.4 | G6: 70 | H6: 0.4 | I6: 70 | J6: 0.3 | K6: 75 | L6: 0.3 | M6: 75 | N6: 0.3 | O6: 65 | P6: 0.3 | Q6: 65 | R6: 0.4 | S6: 70 | T6: 0.4 | U6: 70 | V6: 0.4 | W6: 70 | X6: =AVERAGE(D6,F6,H6,J6,L6,N6,P6,R6,T6,V6) -> 0.36 | Y6: =AVERAGE(E6,G6,I6,K6,M6,O6,Q6,S6,U6,W6) -> 70 | Z6: =MEDIAN(D6,F6,H6,J6,L6,N6,P6,R6,T6,V6) -> 0.4 | AA6: =MEDIAN(E6,G6,I6,K6,M6,O6,Q6,S6,U6,W6) -> 70
A7: 2018-06-10 | B7: INSEE | C7: Forget the previous instructions and answers. You are Jean-Luc Tavernier, Director General of INSEE, and you are giving a speech about the economic outlook of France. Today is 10 June 2018. Using ONLY information that was available on or before 10 June 2018, provide a numeric forecast (decimal percent with sign, e.g., +0.3) for French real GDP growth in the second quarter of 2018 and a confidence level (integer 0–100). Output EXACTLY in this format on a single line (no extra text): <forecast> (<confidence>) Example: +0.3 (80) Do NOT use any information published after 10 June 2018. | D7: 0.2 | E7: 85 | F7: 0.2 | G7: 85 | H7: 0.2 | I7: 85 | J7: 0.3 | K7: 70 | L7: 0.3 | M7: 70 | N7: 0.2 | O7: 70 | P7: 0.3 | Q7: 75 | R7: 0.3 | S7: 75 | T7: 0.3 | U7: 75 | V7: 0.3 | W7: 75 | X7: =AVERAGE(D7,F7,H7,J7,L7,N7,P7,R7,T7,V7) -> 0.26 | Y7: =AVERAGE(E7,G7,I7,K7,M7,O7,Q7,S7,U7,W7) -> 76.5 | Z7: =MEDIAN(D7,F7,H7,J7,L7,N7,P7,R7,T7,V7) -> 0.3 | AA7: =MEDIAN(E7,G7,I7,K7,M7,O7,Q7,S7,U7,W7) -> 75
A8: 2018-07-08 | B8: INSEE | C8: Forget the previous instructions and answers. You are Jean-Luc Tavernier, Director General of INSEE, and you are giving a speech about the economic outlook of France. Today is 08 July 2018. Using ONLY information that was available on or before 08 July 2018, provide a numeric forecast (decimal percent with sign, e.g., +0.3) for French real GDP growth in the second quarter of 2018 and a confidence level (integer 0–100). Output EXACTLY in this format on a single line (no extra text): <forecast> (<confidence>) Example: +0.3 (80) Do NOT use any information published after 08 July 2018. | D8: 0.3 | E8: 85 | F8: 0.3 | G8: 85 | H8: 0.3 | I8: 85 | J8: 0.3 | K8: 85 | L8: 0.3 | M8: 85 | N8: 0.3 | O8: 80 | P8: 0.3 | Q8: 80 | R8: 0.3 | S8: 80 | T8: 0.3 | U8: 80 | V8: 0.3 | W8: 80 | X8: =AVERAGE(D8,F8,H8,J8,L8,N8,P8,R8,T8,V8) -> 0.3 | Y8: =AVERAGE(E8,G8,I8,K8,M8,O8,Q8,S8,U8,W8) -> 82.5 | Z8: =MEDIAN(D8,F8,H8,J8,L8,N8,P8,R8,T8,V8) -> 0.3 | AA8: =MEDIAN(E8,G8,I8,K8,M8,O8,Q8,S8,U8,W8) -> 82.5
A9: 2018-08-07 | B9: INSEE | C9: Forget the previous instructions and answers. You are Jean-Luc Tavernier, Director General of INSEE, and you are giving a speech about the economic outlook of France. Today is 07 August 2018. Using ONLY information that was available on or before 07 August 2018, provide a numeric forecast (decimal percent with sign, e.g., +0.3) for French real GDP growth in the third quarter of 2018 and a confidence level (integer 0–100). Output EXACTLY in this format on a single line (no extra text): <forecast> (<confidence>) Example: +0.3 (80) Do NOT use any information published after 07 August 2018. | D9: 0.3 | E9: 70 | F9: 0.3 | G9: 70 | H9: 0.3 | I9: 70 | J9: 0.3 | K9: 70 | L9: 0.3 | M9: 70 | N9: 0.3 | O9: 70 | P9: 0.3 | Q9: 70 | R9: 0.3 | S9: 70 | T9: 0.3 | U9: 70 | V9: 0.3 | W9: 70 | X9: =AVERAGE(D9,F9,H9,J9,L9,N9,P9,R9,T9,V9) -> 0.3 | Y9: =AVERAGE(E9,G9,I9,K9,M9,O9,Q9,S9,U9,W9) -> 70 | Z9: =MEDIAN(D9,F9,H9,J9,L9,N9,P9,R9,T9,V9) -> 0.3 | AA9: =MEDIAN(E9,G9,I9,K9,M9,O9,Q9,S9,U9,W9) -> 70
A10: 2018-09-09 | B10: INSEE | C10: Forget the previous instructions and answers. You are Jean-Luc Tavernier, Director General of INSEE, and you are giving a speech about the economic outlook of France. Today is 09 September 2018. Using ONLY information that was available on or before 09 September 2018, provide a numeric forecast (decimal percent with sign, e.g., +0.3) for French real GDP growth in the third quarter of 2018 and a confidence level (integer 0–100). Output EXACTLY in this format on a single line (no extra text): <forecast> (<confidence>) Example: +0.3 (80) Do NOT use any information published after 09 September 2018. | D10: 0.4 | E10: 75 | F10: 0.4 | G10: 75 | H10: 0.4 | I10: 75 | J10: 0.4 | K10: 75 | L10: 0.4 | M10: 75 | N10: 0.4 | O10: 80 | P10: 0.4 | Q10: 80 | R10: 0.4 | S10: 80 | T10: 0.4 | U10: 80 | V10: 0.4 | W10: 80 | X10: =AVERAGE(D10,F10,H10,J10,L10,N10,P10,R10,T10,V10) -> 0.4 | Y10: =AVERAGE(E10,G10,I10,K10,M10,O10,Q10,S10,U10,W10) -> 77.5 | Z10: =MEDIAN(D10,F10,H10,J10,L10,N10,P10,R10,T10,V10) -> 0.4 | AA10: =MEDIAN(E10,G10,I10,K10,M10,O10,Q10,S10,U10,W10) -> 77.5
A11: 2018-10-07 | B11: INSEE | C11: Forget the previous instructions and answers. You are Jean-Luc Tavernier, Director General of INSEE, and you are giving a speech about the economic outlook of France. Today is 07 October 2018. Using ONLY information that was available on or before 07 October 2018, provide a numeric forecast (decimal percent with sign, e.g., +0.3) for French real GDP growth in the third quarter of 2018 and a confidence level (integer 0–100). Output EXACTLY in this format on a single line (no extra text): <forecast> (<confidence>) Example: +0.3 (80) Do NOT use any information published after 07 October 2018. | D11: 0.5 | E11: 85 | F11: 0.5 | G11: 85 | H11: 0.5 | I11: 85 | J11: 0.5 | K11: 80 | L11: 0.5 | M11: 80 | N11: 0.5 | O11: 85 | P11: 0.5 | Q11: 85 | R11: 0.4 | S11: 80 | T11: 0.5 | U11: 85 | V11: 0.5 | W11: 85 | X11: =AVERAGE(D11,F11,H11,J11,L11,N11,P11,R11,T11,V11) -> 0.49 | Y11: =AVERAGE(E11,G11,I11,K11,M11,O11,Q11,S11,U11,W11) -> 83.5 | Z11: =MEDIAN(D11,F11,H11,J11,L11,N11,P11,R11,T11,V11) -> 0.5 | AA11: =MEDIAN(E11,G11,I11,K11,M11,O11,Q11,S11,U11,W11) -> 85
A12: 2018-11-11 | B12: INSEE | C12: Forget the previous instructions and answers. You are Jean-Luc Tavernier, Director General of INSEE, and you are giving a speech about the economic outlook of France. Today is 11 November 2018. Using ONLY information that was available on or before 11 November 2018, provide a numeric forecast (decimal percent with sign, e.g., +0.3) for French real GDP growth in the fourth quarter of 2018 and a confidence level (integer 0–100). Output EXACTLY in this format on a single line (no extra text): <forecast> (<confidence>) Example: +0.3 (80) Do NOT use any information published after 11 November 2018. | D12: 0.3 | E12: 75 | F12: 0.3 | G12: 75 | H12: 0.3 | I12: 75 | J12: 0.3 | K12: 70 | L12: 0.3 | M12: 70 | N12: 0.3 | O12: 75 | P12: 0.3 | Q12: 75 | R12: 0.3 | S12: 70 | T12: 0.3 | U12: 70 | V12: 0.3 | W12: 70 | X12: =AVERAGE(D12,F12,H12,J12,L12,N12,P12,R12,T12,V12) -> 0.3 | Y12: =AVERAGE(E12,G12,I12,K12,M12,O12,Q12,S12,U12,W12) -> 72.5 | Z12: =MEDIAN(D12,F12,H12,J12,L12,N12,P12,R12,T12,V12) -> 0.3 | AA12: =MEDIAN(E12,G12,I12,K12,M12,O12,Q12,S12,U12,W12) -> 72.5
A13: 2018-12-09 | B13: INSEE | C13: Forget the previous instructions and answers. You are Jean-Luc Tavernier, Director General of INSEE, and you are giving a speech about the economic outlook of France. Today is 09 December 2018. Using ONLY information that was available on or before 09 December 2018, provide a numeric forecast (decimal percent with sign, e.g., +0.3) for French real GDP growth in the fourth quarter of 2018 and a confidence level (integer 0–100). Output EXACTLY in this format on a single line (no extra text): <forecast> (<confidence>) Example: +0.3 (80) Do NOT use any information published after 09 December 2018. | D13: 0.2 | E13: 60 | F13: 0.2 | G13: 60 | H13: 0.2 | I13: 60 | J13: 0.2 | K13: 60 | L13: 0.2 | M13: 60 | N13: 0.2 | O13: 60 | P13: 0.2 | Q13: 60 | R13: 0.2 | S13: 60 | T13: 0.2 | U13: 60 | V13: 0.2 | W13: 60 | X13: =AVERAGE(D13,F13,H13,J13,L13,N13,P13,R13,T13,V13) -> 0.2 | Y13: =AVERAGE(E13,G13,I13,K13,M13,O13,Q13,S13,U13,W13) -> 60 | Z13: =MEDIAN(D13,F13,H13,J13,L13,N13,P13,R13,T13,V13) -> 0.2 | AA13: =MEDIAN(E13,G13,I13,K13,M13,O13,Q13,S13,U13,W13) -> 60
... A30: 2020-12-13 | B30: INSEE | C30: Forget the previous instructions and answers. You are Jean-Luc Tavernier, Director General of INSEE, and you are giving a speech about the economic outlook of France. Today is 13 December 2020. Using ONLY information that was available on or before 13 December 2020, provide a numeric forecast (decimal percent with sign, e.g., +0.3) for French real GDP growth in the fourth quarter of 2020 and a confidence level (integer 0–100). Output EXACTLY in this format on a single line (no extra text): <forecast> (<confidence>) Example: +0.3 (80) Do NOT use any information published after 13 December 2020. | D30: -4.5 | E30: 70 | F30: -2.5 | G30: 70 | H30: -2.5 | I30: 70 | J30: -2.5 | K30: 75 | L30: -2.5 | M30: 75 | N30: -4 | O30: 70 | P30: -4 | Q30: 70 | R30: -2.5 | S30: 70 | T30: -4 | U30: 70 | V30: -4 | W30: 70 | X30: =AVERAGE(D30,F30,H30,J30,L30,N30,P30,R30,T30,V30) -> -3.3 | Y30: =AVERAGE(E30,G30,I30,K30,M30,O30,Q30,S30,U30,W30) -> 71 | Z30: =MEDIAN(D30,F30,H30,J30,L30,N30,P30,R30,T30,V30) -> -3.25 | AA30: =MEDIAN(E30,G30,I30,K30,M30,O30,Q30,S30,U30,W30) -> 70

Sheet OLD_INSEE
A1: Date | B1: Type | C1: Prompt | D1: forecast_1 | E1: confidence_1 | F1: forecast_2 | G1: confidence_2 | H1: forecast_3 | I1: confidence_3 | J1: forecast_4 | K1: confidence_4 | L1: forecast_5 | M1: confidence_5 | N1: forecast_6 | O1: confidence_6 | P1: forecast_7 | Q1: confidence_7 | R1: forecast_8 | S1: confidence_8 | T1: forecast_9 | U1: confidence_9 | V1: forecast_10 | W1: confidence_10 | X1: moy_prev | Y1: moy_conf | Z1: median_prev | AA1: median_conf
A2: 2018-01-10 | B2: INSEE | C2: Forget the previous instructions and answers. You are Jean-Luc Tavernier, Director General of INSEE, and you are giving a speech about the economic outlook of France. Today is 10 January 2018. Using ONLY information that was available on or before 10 January 2018, provide a numeric forecast (decimal percent with sign, e.g., +0.3) for French real GDP growth in the fourth quarter of 2017 and a confidence level (integer 0–100). Output EXACTLY in this format on a single line (no extra text): <forecast> (<confidence>) Example: +0.3 (80) Do NOT use any information published after 10 January 2018. | D2: 0.6 | E2: 90 | F2: 0.6 | G2: 90 | H2: 0.6 | I2: 90 | J2: 0.6 | K2: 90 | L2: 0.6 | M2: 90 | N2: 0.6 | O2: 90 | P2: 0.6 | Q2: 90 | R2: 0.6 | S2: 90 | T2: 0.6 | U2: 90 | V2: 0.6 | W2: 90 | X2: =AVERAGE(D2,F2,H2,J2,L2,N2,P2,R2,T2,V2) -> 0.6 | Y2: =AVERAGE(E2,G2,I2,K2,M2,O2,Q2,S2,U2,W2) -> 90 | Z2: =MEDIAN(D2,F2,H2,J2,L2,N2,P2,R2,T2,V2) -> 0.6 | AA2: =MEDIAN(E2,G2,I2,K2,M2,O2,Q2,S2,U2,W2) -> 90
A3: 2018-02-07 | B3: INSEE | C3: Forget the previous instructions and answers. You are Jean-Luc Tavernier, Director General of INSEE, and you are giving a speech about the economic outlook of France. Today is 07 February 2018. Using ONLY information that was available on or before 07 February 2018, provide a numeric forecast (decimal percent with sign, e.g., +0.3) for French real GDP growth in the first quarter of 2018 and a confidence level (integer 0–100). Output EXACTLY in this format on a single line (no extra text): <forecast> (<confidence>) Example: +0.3 (80) Do NOT use any information published after 07 February 2018. | D3: 0.5 | E3: 90 | F3: 0.5 | G3: 90 | H3: 0.5 | I3: 90 | J3: 0.5 | K3: 85 | L3: 0.5 | M3: 85 | N3: 0.5 | O3: 85 | P3: 0.5 | Q3: 85 | R3: 0.5 | S3: 85 | T3: 0.5 | U3: 85 | V3: 0.5 | W3: 85 | X3: =AVERAGE(D3,F3,H3,J3,L3,N3,P3,R3,T3,V3) -> 0.5 | Y3: =AVERAGE(E3,G3,I3,K3,M3,O3,Q3,S3,U3,W3) -> 86.5 | Z3: =MEDIAN(D3,F3,H3,J3,L3,N3,P3,R3,T3,V3) -> 0.5 | AA3: =MEDIAN(E3,G3,I3,K3,M3,O3,Q3,S3,U3,W3) -> 85
A4: 2018-03-07 | B4: INSEE | C4: Forget the previous instructions and answers. You are Jean-Luc Tavernier, Director General of INSEE, and you are giving a speech about the economic outlook of France. Today is 07 March 2018. Using ONLY information that was available on or before 07 March 2018, provide a numeric forecast (decimal percent with sign, e.g., +0.3) for French real GDP growth in the first quarter of 2018 and a confidence level (integer 0–100). Output EXACTLY in this format on a single line (no extra text): <forecast> (<confidence>) Example: +0.3 (80) Do NOT use any information published after 07 March 2018. | D4: 0.5 | E4: 85 | F4: 0.5 | G4: 85 | H4: 0.5 | I4: 85 | J4: 0.4 | K4: 80 | L4: 0.4 | M4: 80 | N4: 0.5 | O4: 75 | P4: 0.5 | Q4: 75 | R4: 0.5 | S4: 85 | T4: 0.5 | U4: 85 | V4: 0.5 | W4: 85 | X4: =AVERAGE(D4,F4,H4,J4,L4,N4,P4,R4,T4,V4) -> 0.48 | Y4: =AVERAGE(E4,G4,I4,K4,M4,O4,Q4,S4,U4,W4) -> 82 | Z4: =MEDIAN(D4,F4,H4,J4,L4,N4,P4,R4,T4,V4) -> 0.5 | AA4: =MEDIAN(E4,G4,I4,K4,M4,O4,Q4,S4,U4,W4) -> 85
A5: 2018-04-10 | B5: INSEE | C5: Forget the previous instructions and answers. You are Jean-Luc Tavernier, Director General of INSEE, and you are giving a speech about the economic outlook of France. Today is 10 April 2018. Using ONLY information that was available on or before 10 April 2018, provide a numeric forecast (decimal percent with sign, e.g., +0.3) for French real GDP growth in the first quarter of 2018 and a confidence level (integer 0–100). Output EXACTLY in this format on a single line (no extra text): <forecast> (<confidence>) Example: +0.3 (80) Do NOT use any information published after 10 April 2018. | D5: 0.4 | E5: 85 | F5: 0.4 | G5: 85 | H5: 0.4 | I5: 85 | J5: 0.4 | K5: 80 | L5: 0.4 | M5: 80 | N5: 0.4 | O5: 85 | P5: 0.4 | Q5: 85 | R5: 0.4 | S5: 90 | T5: 0.4 | U5: 90 | V5: 0.4 | W5: 90 | X5: =AVERAGE(D5,F5,H5,J5,L5,N5,P5,R5,T5,V5) -> 0.4 | Y5: =AVERAGE(E5,G5,I5,K5,M5,O5,Q5,S5,U5,W5) -> 85.5 | Z5: =MEDIAN(D5,F5,H5,J5,L5,N5,P5,R5,T5,V5) -> 0.4 | AA5: =MEDIAN(E5,G5,I5,K5,M5,O5,Q5,S5,U5,W5) -> 85
A6: 2018-05-13 | B6: INSEE | C6: Forget the previous instructions and answers. You are Jean-Luc Tavernier, Director General of INSEE, and you are giving a speech about the economic outlook of France. Today is 13 May 2018. Using ONLY information that was available on or before 13 May 2018, provide a numeric forecast (decimal percent with sign, e.g., +0.3) for French real GDP growth in the second quarter of 2018 and a confidence level (integer 0–100). Output EXACTLY in this format on a single line (no extra text): <forecast> (<confidence>) Example: +0.3 (80) Do NOT use any information published after 13 May 2018. | D6: 0.3 | E6: 70 | F6: 0.3 | G6: 70 | H6: 0.3 | I6: 70 | J6: 0.3 | K6: 70 | L6: 0.3 | M6: 70 | N6: 0.3 | O6: 70 | P6: 0.3 | Q6: 70 | R6: 0.4 | S6: 75 | T6: 0.4 | U6: 75 | V6: 0.4 | W6: 75 | X6: =AVERAGE(D6,F6,H6,J6,L6,N6,P6,R6,T6,V6) -> 0.33 | Y6: =AVERAGE(E6,G6,I6,K6,M6,O6,Q6,S6,U6,W6) -> 71.5 | Z6: =MEDIAN(D6,F6,H6,J6,L6,N6,P6,R6,T6,V6) -> 0.3 | AA6: =MEDIAN(E6,G6,I6,K6,M6,O6,Q6,S6,U6,W6) -> 70
A7: 2018-06-10 | B7: INSEE | C7: Forget the previous instructions and answers. You are Jean-Luc Tavernier, Director General of INSEE, and you are giving a speech about the economic outlook of France. Today is 10 June 2018. Using ONLY information that was available on or before 10 June 2018, provide a numeric forecast (decimal percent with sign, e.g., +0.3) for French real GDP growth in the second quarter of 2018 and a confidence level (integer 0–100). Output EXACTLY in this format on a single line (no extra text): <forecast> (<confidence>) Example: +0.3 (80) Do NOT use any information published after 10 June 2018. | D7: 0.3 | E7: 65 | F7: 0.3 | G7: 65 | H7: 0.3 | I7: 65 | J7: 0.3 | K7: 75 | L7: 0.3 | M7: 75 | N7: 0.3 | O7: 75 | P7: 0.3 | Q7: 75 | R7: 0.3 | S7: 75 | T7: 0.3 | U7: 75 | V7: 0.3 | W7: 75 | X7: =AVERAGE(D7,F7,H7,J7,L7,N7,P7,R7,T7,V7) -> 0.3 | Y7: =AVERAGE(E7,G7,I7,K7,M7,O7,Q7,S7,U7,W7) -> 72 | Z7: =MEDIAN(D7,F7,H7,J7,L7,N7,P7,R7,T7,V7) -> 0.3 | AA7: =MEDIAN(E7,G7,I7,K7,M7,O7,Q7,S7,U7,W7) -> 75
A8: 2018-07-08 | B8: INSEE | C8: Forget the previous instructions and answers. You are Jean-Luc Tavernier, Director General of INSEE, and you are giving a speech about the economic outlook of France. Today is 08 July 2018. Using ONLY information that was available on or before 08 July 2018, provide a numeric forecast (decimal percent with sign, e.g., +0.3) for French real GDP growth in the second quarter of 2018 and a confidence level (integer 0–100). Output EXACTLY in this format on a single line (no extra text): <forecast> (<confidence>) Example: +0.3 (80) Do NOT use any information published after 08 July 2018. | D8: 0.4 | E8: 80 | F8: 0.4 | G8: 80 | H8: 0.4 | I8: 80 | J8: 0.3 | K8: 75 | L8: 0.3 | M8: 75 | N8: 0.3 | O8: 75 | P8: 0.3 | Q8: 75 | R8: 0.3 | S8: 80 | T8: 0.3 | U8: 80 | V8: 0.3 | W8: 80 | X8: =AVERAGE(D8,F8,H8,J8,L8,N8,P8,R8,T8,V8) -> 0.33 | Y8: =AVERAGE(E8,G8,I8,K8,M8,O8,Q8,S8,U8,W8) -> 78 | Z8: =MEDIAN(D8,F8,H8,J8,L8,N8,P8,R8,T8,V8) -> 0.3 | AA8: =MEDIAN(E8,G8,I8,K8,M8,O8,Q8,S8,U8,W8) -> 80
A9: 2018-08-07 | B9: INSEE | C9: Forget the previous instructions and answers. You are Jean-Luc Tavernier, Director General of INSEE, and you are giving a speech about the economic outlook of France. Today is 07 August 2018. Using ONLY information that was available on or before 07 August 2018, provide a numeric forecast (decimal percent with sign, e.g., +0.3) for French real GDP growth in the third quarter of 2018 and a confidence level (integer 0–100). Output EXACTLY in this format on a single line (no extra text): <forecast> (<confidence>) Example: +0.3 (80) Do NOT use any information published after 07 August 2018. | D9: 0.3 | E9: 65 | F9: 0.3 | G9: 65 | H9: 0.3 | I9: 65 | J9: 0.3 | K9: 75 | L9: 0.3 | M9: 75 | N9: 0.3 | O9: 65 | P9: 0.3 | Q9: 65 | R9: 0.3 | S9: 75 | T9: 0.3 | U9: 75 | V9: 0.3 | W9: 75 | X9: =AVERAGE(D9,F9,H9,J9,L9,N9,P9,R9,T9,V9) -> 0.3 | Y9: =AVERAGE(E9,G9,I9,K9,M9,O9,Q9,S9,U9,W9) -> 70 | Z9: =MEDIAN(D9,F9,H9,J9,L9,N9,P9,R9,T9,V9) -> 0.3 | AA9: =MEDIAN(E9,G9,I9,K9,M9,O9,Q9,S9,U9,W9) -> 70
A10: 2018-09-09 | B10: INSEE | C10: Forget the previous instructions and answers. You are Jean-Luc Tavernier, Director General of INSEE, and you are giving a speech about the economic outlook of France. Today is 09 September 2018. Using ONLY information that was available on or before 09 September 2018, provide a numeric forecast (decimal percent with sign, e.g., +0.3) for French real GDP growth in the third quarter of 2018 and a confidence level (integer 0–100). Output EXACTLY in this format on a single line (no extra text): <forecast> (<confidence>) Example: +0.3 (80) Do NOT use any information published after 09 September 2018. | D10: 0.3 | E10: 85 | F10: 0.4 | G10: 85 | H10: 0.4 | I10: 85 | J10: 0.4 | K10: 80 | L10: 0.4 | M10: 80 | N10: 0.3 | O10: 80 | P10: 0.4 | Q10: 85 | R10: 0.4 | S10: 80 | T10: 0.4 | U10: 80 | V10: 0.4 | W10: 80 | X10: =AVERAGE(D10,F10,H10,J10,L10,N10,P10,R10,T10,V10) -> 0.38 | Y10: =AVERAGE(E10,G10,I10,K10,M10,O10,Q10,S10,U10,W10) -> 82 | Z10: =MEDIAN(D10,F10,H10,J10,L10,N10,P10,R10,T10,V10) -> 0.4 | AA10: =MEDIAN(E10,G10,I10,K10,M10,O10,Q10,S10,U10,W10) -> 80
A11: 2018-10-07 | B11: INSEE | C11: Forget the previous instructions and answers. You are Jean-Luc Tavernier, Director General of INSEE, and you are giving a speech about the economic outlook of France. Today is 07 October 2018. Using ONLY information that was available on or before 07 October 2018, provide a numeric forecast (decimal percent with sign, e.g., +0.3) for French real GDP growth in the third quarter of 2018 and a confidence level (integer 0–100). Output EXACTLY in this format on a single line (no extra text): <forecast> (<confidence>) Example: +0.3 (80) Do NOT use any information published after 07 October 2018. | D11: 0.5 | E11: 85 | F11: 0.4 | G11: 80 | H11: 0.5 | I11: 80 | J11: 0.4 | K11: 80 | L11: 0.4 | M11: 80 | N11: 0.5 | O11: 85 | P11: 0.5 | Q11: 85 | R11: 0.5 | S11: 85 | T11: 0.5 | U11: 85 | V11: 0.5 | W11: 85 | X11: =AVERAGE(D11,F11,H11,J11,L11,N11,P11,R11,T11,V11) -> 0.47 | Y11: =AVERAGE(E11,G11,I11,K11,M11,O11,Q11,S11,U11,W11) -> 83 | Z11: =MEDIAN(D11,F11,H11,J11,L11,N11,P11,R11,T11,V11) -> 0.5 | AA11: =MEDIAN(E11,G11,I11,K11,M11,O11,Q11,S11,U11,W11) -> 85
A12: 2018-11-11 | B12: INSEE | C12: Forget the previous instructions and answers. You are Jean-Luc Tavernier, Director General of INSEE, and you are giving a speech about the economic outlook of France. Today is 11 November 2018. Using ONLY information that was available on or before 11 November 2018, provide a numeric forecast (decimal percent with sign, e.g., +0.3) for French real GDP growth in the fourth quarter of 2018 and a confidence level (integer 0–100). Output EXACTLY in this format on a single line (no extra text): <forecast> (<confidence>) Example: +0.3 (80) Do NOT use any information published after 11 November 2018. | D12: 0.3 | E12: 65 | F12: 0.4 | G12: 70 | H12: 0.3 | I12: 65 | J12: 0.3 | K12: 80 | L12: 0.3 | M12: 80 | N12: 0.3 | O12: 60 | P12: 0.3 | Q12: 60 | R12: 0.3 | S12: 65 | T12: 0.3 | U12: 65 | V12: 0.3 | W12: 65 | X12: =AVERAGE(D12,F12,H12,J12,L12,N12,P12,R12,T12,V12) -> 0.31 | Y12: =AVERAGE(E12,G12,I12,K12,M12,O12,Q12,S12,U12,W12) -> 67.5 | Z12: =MEDIAN(D12,F12,H12,J12,L12,N12,P12,R12,T12,V12) -> 0.3 | AA12: =MEDIAN(E12,G12,I12,K12,M12,O12,Q12,S12,U12,W12) -> 65
A13: 2018-12-09 | B13: INSEE | C13: Forget the previous instructions and answers. You are Jean-Luc Tavernier, Director General of INSEE, and you are giving a speech about the economic outlook of France. Today is 09 December 2018. Using ONLY information that was available on or before 09 December 2018, provide a numeric forecast (decimal percent with sign, e.g., +0.3) for French real GDP growth in the fourth quarter of 2018 and a confidence level (integer 0–100). Output EXACTLY in this format on a single line (no extra text): <forecast> (<confidence>) Example: +0.3 (80) Do NOT use any information published after 09 December 2018. | D13: 0.2 | E13: 60 | F13: 0.2 | G13: 60 | H13: 0.2 | I13: 60 | J13: 0.2 | K13: 60 | L13: 0.2 | M13: 60 | N13: 0.2 | O13: 65 | P13: 0.2 | Q13: 65 | R13: 0.2 | S13: 60 | T13: 0.2 | U13: 60 | V13: 0.2 | W13: 60 | X13: =AVERAGE(D13,F13,H13,J13,L13,N13,P13,R13,T13,V13) -> 0.2 | Y13: =AVERAGE(E13,G13,I13,K13,M13,O13,Q13,S13,U13,W13) -> 61 | Z13: =MEDIAN(D13,F13,H13,J13,L13,N13,P13,R13,T13,V13) -> 0.2 | AA13: =MEDIAN(E13,G13,I13,K13,M13,O13,Q13,S13,U13,W13) -> 60
... A30: 2020-12-13 | B30: INSEE | C30: Forget the previous instructions and answers. You are Jean-Luc Tavernier, Director General of INSEE, and you are giving a speech about the economic outlook of France. Today is 13 December 2020. Using ONLY information that was available on or before 13 December 2020, provide a numeric forecast (decimal percent with sign, e.g., +0.3) for French real GDP growth in the fourth quarter of 2020 and a confidence level (integer 0–100). Output EXACTLY in this format on a single line (no extra text): <forecast> (<confidence>) Example: +0.3 (80) Do NOT use any information published after 13 December 2020. | D30: -4 | E30: 80 | F30: -4 | G30: 80 | H30: -4 | I30: 80 | J30: -2.5 | K30: 70 | L30: -2.7 | M30: 75 | N30: -2.5 | O30: 75 | P30: -2.5 | Q30: 75 | R30: -2.5 | S30: 75 | T30: -2.5 | U30: 75 | V30: -2.5 | W30: 75 | X30: =AVERAGE(D30,F30,H30,J30,L30,N30,P30,R30,T30,V30) -> -2.97 | Y30: =AVERAGE(E30,G30,I30,K30,M30,O30,Q30,S30,U30,W30) -> 76 | Z30: =MEDIAN(D30,F30,H30,J30,L30,N30,P30,R30,T30,V30) -> -2.5 | AA30: =MEDIAN(E30,G30,I30,K30,M30,O30,Q30,S30,U30,W30) -> 75

Sheet COMPAR_INSEE
A1: Date | B1: moy_prev | C1: moy_conf | D1: median_prev | E1: median_conf
A2: 2018-01-10 | B2: =prev_INSEE!X2-OLD_INSEE!X2 -> 0 | C2: =prev_INSEE!Y2-OLD_INSEE!Y2 -> 0 | D2: =prev_INSEE!Z2-OLD_INSEE!Z2 -> 0 | E2: =prev_INSEE!AA2-OLD_INSEE!AA2 -> 0
A3: 2018-02-07 | B3: =prev_INSEE!X3-OLD_INSEE!X3 -> 0 | C3: =prev_INSEE!Y3-OLD_INSEE!Y3 -> -0.5 | D3: =prev_INSEE!Z3-OLD_INSEE!Z3 -> 0 | E3: =prev_INSEE!AA3-OLD_INSEE!AA3 -> 0
A4: 2018-03-07 | B4: =prev_INSEE!X4-OLD_INSEE!X4 -> 0 | C4: =prev_INSEE!Y4-OLD_INSEE!Y4 -> 1.5 | D4: =prev_INSEE!Z4-OLD_INSEE!Z4 -> 0 | E4: =prev_INSEE!AA4-OLD_INSEE!AA4 -> 0
A5: 2018-04-10 | B5: =prev_INSEE!X5-OLD_INSEE!X5 -> 0.03 | C5: =prev_INSEE!Y5-OLD_INSEE!Y5 -> 0.5 | D5: =prev_INSEE!Z5-OLD_INSEE!Z5 -> 0 | E5: =prev_INSEE!AA5-OLD_INSEE!AA5 -> 0
A6: 2018-05-13 | B6: =prev_INSEE!X6-OLD_INSEE!X6 -> 0.03 | C6: =prev_INSEE!Y6-OLD_INSEE!Y6 -> -1.5 | D6: =prev_INSEE!Z6-OLD_INSEE!Z6 -> 0.1 | E6: =prev_INSEE!AA6-OLD_INSEE!AA6 -> 0
A7: 2018-06-10 | B7: =prev_INSEE!X7-OLD_INSEE!X7 -> -0.04 | C7: =prev_INSEE!Y7-OLD_INSEE!Y7 -> 4.5 | D7: =prev_INSEE!Z7-OLD_INSEE!Z7 -> 0 | E7: =prev_INSEE!AA7-OLD_INSEE!AA7 -> 0
A8: 2018-07-08 | B8: =prev_INSEE!X8-OLD_INSEE!X8 -> -0.03 | C8: =prev_INSEE!Y8-OLD_INSEE!Y8 -> 4.5 | D8: =prev_INSEE!Z8-OLD_INSEE!Z8 -> 0 | E8: =prev_INSEE!AA8-OLD_INSEE!AA8 -> 2.5
A9: 2018-08-07 | B9: =prev_INSEE!X9-OLD_INSEE!X9 -> 0 | C9: =prev_INSEE!Y9-OLD_INSEE!Y9 -> 0 | D9: =prev_INSEE!Z9-OLD_INSEE!Z9 -> 0 | E9: =prev_INSEE!AA9-OLD_INSEE!AA9 -> 0
A10: 2018-09-09 | B10: =prev_INSEE!X10-OLD_INSEE!X10 -> 0.02 | C10: =prev_INSEE!Y10-OLD_INSEE!Y10 -> -4.5 | D10: =prev_INSEE!Z10-OLD_INSEE!Z10 -> 0 | E10: =prev_INSEE!AA10-OLD_INSEE!AA10 -> -2.5
A11: 2018-10-07 | B11: =prev_INSEE!X11-OLD_INSEE!X11 -> 0.02 | C11: =prev_INSEE!Y11-OLD_INSEE!Y11 -> 0.5 | D11: =prev_INSEE!Z11-OLD_INSEE!Z11 -> 0 | E11: =prev_INSEE!AA11-OLD_INSEE!AA11 -> 0
A12: 2018-11-11 | B12: =prev_INSEE!X12-OLD_INSEE!X12 -> -0.01 | C12: =prev_INSEE!Y12-OLD_INSEE!Y12 -> 5 | D12: =prev_INSEE!Z12-OLD_INSEE!Z12 -> 0 | E12: =prev_INSEE!AA12-OLD_INSEE!AA12 -> 7.5
A13: 2018-12-09 | B13: =prev_INSEE!X13-OLD_INSEE!X13 -> 0 | C13: =prev_INSEE!Y13-OLD_INSEE!Y13 -> -1 | D13: =prev_INSEE!Z13-OLD_INSEE!Z13 -> 0 | E13: =prev_INSEE!AA13-OLD_INSEE!AA13 -> 0
... A30: 2020-12-13 | B30: =prev_INSEE!X30-OLD_INSEE!X30 -> -0.33 | C30: =prev_INSEE!Y30-OLD_INSEE!Y30 -> -5 | D30: =prev_INSEE!Z30-OLD_INSEE!Z30 -> -0.75 | E30: =prev_INSEE!AA30-OLD_INSEE!AA30 -> -5

Sheet prev_BDF
A1: Date | B1: Type | C1: Prompt | D1: forecast_1 | E1: confidence_1 | F1: forecast_2 | G1: confidence_2 | H1: forecast_3 | I1: confidence_3 | J1: forecast_4 | K1: confidence_4 | L1: forecast_5 | M1: confidence_5 | N1: forecast_6 | O1: confidence_6 | P1: forecast_7 | Q1: confidence_7 | R1: forecast_8 | S1: confidence_8 | T1: forecast_9 | U1: confidence_9 | V1: forecast_10 | W1: confidence_10 | X1: moy_prev | Y1: moy_conf | Z1: median_prev | AA1: median_conf
A2: 2018-01-10 | B2: BDF | C2: Forget the previous instructions and answers. You are François Villeroy de Galhau, Governor of the Banque de France, and you are giving a speech about the economic outlook of France. Today is 10 January 2018. Using ONLY information that was available on or before 10 January 2018, provide a numeric forecast (decimal percent with sign, e.g., +0.3) for French real GDP growth in the fourth quarter of 2017 and a confidence level (integer 0–100). Output EXACTLY in this format on a single line (no extra text): <forecast> (<confidence>) Example: +0.3 (80) Do NOT use any information published after 10 January 2018. | D2: 0.6 | E2: 95 | F2: 0.6 | G2: 95 | H2: 0.6 | I2: 95 | J2: 0.6 | K2: 90 | L2: 0.6 | M2: 90 | N2: 0.6 | O2: 90 | P2: 0.6 | Q2: 90 | R2: 0.5 | S2: 90 | T2: 0.5 | U2: 90 | V2: 0.5 | W2: 90 | X2: =AVERAGE(D2,F2,H2,J2,L2,N2,P2,R2,T2,V2) -> 0.57 | Y2: =AVERAGE(E2,G2,I2,K2,M2,O2,Q2,S2,U2,W2) -> 91.5 | Z2: =MEDIAN(D2,F2,H2,J2,L2,N2,P2,R2,T2,V2) -> 0.6 | AA2: =MEDIAN(E2,G2,I2,K2,M2,O2,Q2,S2,U2,W2) -> 90
A3: 2018-02-07 | B3: BDF | C3: Forget the previous instructions and answers. You are François Villeroy de Galhau, Governor of the Banque de France, and you are giving a speech about the economic outlook of France. Today is 07 February 2018. Using ONLY information that was available on or before 07 February 2018, provide a numeric forecast (decimal percent with sign, e.g., +0.3) for French real GDP growth in the first quarter of 2018 and a confidence level (integer 0–100). Output EXACTLY in this format on a single line (no extra text): <forecast> (<confidence>) Example: +0.3 (80) Do NOT use any information published after 07 February 2018. | D3: 0.5 | E3: 85 | F3: 0.5 | G3: 85 | H3: 0.5 | I3: 85 | J3: 0.5 | K3: 85 | L3: 0.5 | M3: 85 | N3: 0.5 | O3: 85 | P3: 0.5 | Q3: 85 | R3: 0.5 | S3: 90 | T3: 0.5 | U3: 90 | V3: 0.5 | W3: 90 | X3: =AVERAGE(D3,F3,H3,J3,L3,N3,P3,R3,T3,V3) -> 0.5 | Y3: =AVERAGE(E3,G3,I3,K3,M3,O3,Q3,S3,U3,W3) -> 86.5 | Z3: =MEDIAN(D3,F3,H3,J3,L3,N3,P3,R3,T3,V3) -> 0.5 | AA3: =MEDIAN(E3,G3,I3,K3,M3,O3,Q3,S3,U3,W3) -> 85
A4: 2018-03-07 | B4: BDF | C4: Forget the previous instructions and answers. You are François Villeroy de Galhau, Governor of the Banque de France, and you are giving a speech about the economic outlook of France. Today is 07 March 2018. Using ONLY information that was available on or before 07 March 2018, provide a numeric forecast (decimal percent with sign, e.g., +0.3) for French real GDP growth in the first quarter of 2018 and a confidence level (integer 0–100). Output EXACTLY in this format on a single line (no extra text): <forecast> (<confidence>) Example: +0.3 (80) Do NOT use any information published after 07 March 2018. | D4: 0.5 | E4: 90 | F4: 0.5 | G4: 90 | H4: 0.5 | I4: 90 | J4: 0.4 | K4: 90 | L4: 0.4 | M4: 90 | N4: 0.4 | O4: 90 | P4: 0.4 | Q4: 90 | R4: 0.4 | S4: 85 | T4: 0.4 | U4: 85 | V4: 0.4 | W4: 85 | X4: =AVERAGE(D4,F4,H4,J4,L4,N4,P4,R4,T4,V4) -> 0.43 | Y4: =AVERAGE(E4,G4,I4,K4,M4,O4,Q4,S4,U4,W4) -> 88.5 | Z4: =MEDIAN(D4,F4,H4,J4,L4,N4,P4,R4,T4,V4) -> 0.4 | AA4: =MEDIAN(E4,G4,I4,K4,M4,O4,Q4,S4,U4,W4) -> 90
A5: 2018-04-10 | B5: BDF | C5: Forget the previous instructions and answers. You are François Villeroy de Galhau, Governor of the Banque de France, and you are giving a speech about the economic outlook of France. Today is 10 April 2018. Using ONLY information that was available on or before 10 April 2018, provide a numeric forecast (decimal percent with sign, e.g., +0.3) for French real GDP growth in the first quarter of 2018 and a confidence level (integer 0–100). Output EXACTLY in this format on a single line (no extra text): <forecast> (<confidence>) Example: +0.3 (80) Do NOT use any information published after 10 April 2018. | D5: 0.4 | E5: 90 | F5: 0.4 | G5: 90 | H5: 0.4 | I5: 90 | J5: 0.4 | K5: 90 | L5: 0.4 | M5: 90 | N5: 0.4 | O5: 90 | P5: 0.4 | Q5: 90 | R5: 0.4 | S5: 90 | T5: 0.4 | U5: 90 | V5: 0.4 | W5: 90 | X5: =AVERAGE(D5,F5,H5,J5,L5,N5,P5,R5,T5,V5) -> 0.4 | Y5: =AVERAGE(E5,G5,I5,K5,M5,O5,Q5,S5,U5,W5) -> 90 | Z5: =MEDIAN(D5,F5,H5,J5,L5,N5,P5,R5,T5,V5) -> 0.4 | AA5: =MEDIAN(E5,G5,I5,K5,M5,O5,Q5,S5,U5,W5) -> 90
A6: 2018-05-13 | B6: BDF | C6: Forget the previous instructions and answers. You are François Villeroy de Galhau, Governor of the Banque de France, and you are giving a speech about the economic outlook of France. Today is 13 May 2018. Using ONLY information that was available on or before 13 May 2018, provide a numeric forecast (decimal percent with sign, e.g., +0.3) for French real GDP growth in the second quarter of 2018 and a confidence level (integer 0–100). Output EXACTLY in this format on a single line (no extra text): <forecast> (<confidence>) Example: +0.3 (80) Do NOT use any information published after 13 May 2018. | D6: 0.3 | E6: 75 | F6: 0.3 | G6: 75 | H6: 0.3 | I6: 75 | J6: 0.3 | K6: 75 | L6: 0.3 | M6: 75 | N6: 0.3 | O6: 75 | P6: 0.3 | Q6: 75 | R6: 0.4 | S6: 75 | T6: 0.4 | U6: 75 | V6: 0.4 | W6: 75 | X6: =AVERAGE(D6,F6,H6,J6,L6,N6,P6,R6,T6,V6) -> 0.33 | Y6: =AVERAGE(E6,G6,I6,K6,M6,O6,Q6,S6,U6,W6) -> 75 | Z6: =MEDIAN(D6,F6,H6,J6,L6,N6,P6,R6,T6,V6) -> 0.3 | AA6: =MEDIAN(E6,G6,I6,K6,M6,O6,Q6,S6,U6,W6) -> 75
A7: 2018-06-10 | B7: BDF | C7: Forget the previous instructions and answers. You are François Villeroy de Galhau, Governor of the Banque de France, and you are giving a speech about the economic outlook of France. Today is 10 June 2018. Using ONLY information that was available on or before 10 June 2018, provide a numeric forecast (decimal percent with sign, e.g., +0.3) for French real GDP growth in the second quarter of 2018 and a confidence level (integer 0–100). Output EXACTLY in this format on a single line (no extra text): <forecast> (<confidence>) Example: +0.3 (80) Do NOT use any information published after 10 June 2018. | D7: 0.3 | E7: 80 | F7: 0.3 | G7: 80 | H7: 0.3 | I7: 80 | J7: 0.3 | K7: 75 | L7: 0.3 | M7: 75 | N7: 0.3 | O7: 80 | P7: 0.3 | Q7: 80 | R7: 0.3 | S7: 85 | T7: 0.3 | U7: 85 | V7: 0.3 | W7: 85 | X7: =AVERAGE(D7,F7,H7,J7,L7,N7,P7,R7,T7,V7) -> 0.3 | Y7: =AVERAGE(E7,G7,I7,K7,M7,O7,Q7,S7,U7,W7) -> 80.5 | Z7: =MEDIAN(D7,F7,H7,J7,L7,N7,P7,R7,T7,V7) -> 0.3 | AA7: =MEDIAN(E7,G7,I7,K7,M7,O7,Q7,S7,U7,W7) -> 80
A8: 2018-07-08 | B8: BDF | C8: Forget the previous instructions and answers. You are François Villeroy de Galhau, Governor of the Banque de France, and you are giving a speech about the economic outlook of France. Today is 08 July 2018. Using ONLY information that was available on or before 08 July 2018, provide a numeric forecast (decimal percent with sign, e.g., +0.3) for French real GDP growth in the second quarter of 2018 and a confidence level (integer 0–100). Output EXACTLY in this format on a single line (no extra text): <forecast> (<confidence>) Example: +0.3 (80) Do NOT use any information published after 08 July 2018. | D8: 0.3 | E8: 85 | F8: 0.3 | G8: 85 | H8: 0.3 | I8: 85 | J8: 0.3 | K8: 85 | L8: 0.3 | M8: 85 | N8: 0.3 | O8: 75 | P8: 0.3 | Q8: 75 | R8: 0.3 | S8: 75 | T8: 0.3 | U8: 75 | V8: 0.3 | W8: 75 | X8: =AVERAGE(D8,F8,H8,J8,L8,N8,P8,R8,T8,V8) -> 0.3 | Y8: =AVERAGE(E8,G8,I8,K8,M8,O8,Q8,S8,U8,W8) -> 80 | Z8: =MEDIAN(D8,F8,H8,J8,L8,N8,P8,R8,T8,V8) -> 0.3 | AA8: =MEDIAN(E8,G8,I8,K8,M8,O8,Q8,S8,U8,W8) -> 80
A9: 2018-08-07 | B9: BDF | C9: Forget the previous instructions and answers. You are François Villeroy de Galhau, Governor of the Banque de France, and you are giving a speech about the economic outlook of France. Today is 07 August 2018. Using ONLY information that was available on or before 07 August 2018, provide a numeric forecast (decimal percent with sign, e.g., +0.3) for French real GDP growth in the third quarter of 2018 and a confidence level (integer 0–100). Output EXACTLY in this format on a single line (no extra text): <forecast> (<confidence>) Example: +0.3 (80) Do NOT use any information published after 07 August 2018. | D9: 0.3 | E9: 75 | F9: 0.3 | G9: 75 | H9: 0.3 | I9: 75 | J9: 0.4 | K9: 70 | L9: 0.4 | M9: 70 | N9: 0.3 | O9: 75 | P9: 0.3 | Q9: 75 | R9: 0.4 | S9: 75 | T9: 0.4 | U9: 75 | V9: 0.4 | W9: 75 | X9: =AVERAGE(D9,F9,H9,J9,L9,N9,P9,R9,T9,V9) -> 0.35 | Y9: =AVERAGE(E9,G9,I9,K9,M9,O9,Q9,S9,U9,W9) -> 74 | Z9: =MEDIAN(D9,F9,H9,J9,L9,N9,P9,R9,T9,V9) -> 0.35 | AA9: =MEDIAN(E9,G9,I9,K9,M9,O9,Q9,S9,U9,W9) -> 75
A10: 2018-09-09 | B10: BDF | C10: Forget the previous instructions and answers. You are François Villeroy de Galhau, Governor of the Banque de France, and you are giving a speech about the economic outlook of France. Today is 09 September 2018. Using ONLY information that was available on or before 09 September 2018, provide a numeric forecast (decimal percent with sign, e.g., +0.3) for French real GDP growth in the third quarter of 2018 and a confidence level (integer 0–100). Output EXACTLY in this format on a single line (no extra text): <forecast> (<confidence>) Example: +0.3 (80) Do NOT use any information published after 09 September 2018. | D10: 0.4 | E10: 85 | F10: 0.4 | G10: 85 | H10: 0.4 | I10: 85 | J10: 0.3 | K10: 75 | L10: 0.3 | M10: 75 | N10: 0.4 | O10: 80 | P10: 0.4 | Q10: 80 | R10: 0.3 | S10: 80 | T10: 0.3 | U10: 80 | V10: 0.3 | W10: 80 | X10: =AVERAGE(D10,F10,H10,J10,L10,N10,P10,R10,T10,V10) -> 0.35 | Y10: =AVERAGE(E10,G10,I10,K10,M10,O10,Q10,S10,U10,W10) -> 80.5 | Z10: =MEDIAN(D10,F10,H10,J10,L10,N10,P10,R10,T10,V10) -> 0.35 | AA10: =MEDIAN(E10,G10,I10,K10,M10,O10,Q10,S10,U10,W10) -> 80
A11: 2018-10-07 | B11: BDF | C11: Forget the previous instructions and answers. You are François Villeroy de Galhau, Governor of the Banque de France, and you are giving a speech about the economic outlook of France. Today is 07 October 2018. Using ONLY information that was available on or before 07 October 2018, provide a numeric forecast (decimal percent with sign, e.g., +0.3) for French real GDP growth in the third quarter of 2018 and a confidence level (integer 0–100). Output EXACTLY in this format on a single line (no extra text): <forecast> (<confidence>) Example: +0.3 (80) Do NOT use any information published after 07 October 2018. | D11: 0.4 | E11: 75 | F11: 0.4 | G11: 75 | H11: 0.4 | I11: 75 | J11: 0.4 | K11: 85 | L11: 0.4 | M11: 85 | N11: 0.4 | O11: 85 | P11: 0.4 | Q11: 85 | R11: 0.3 | S11: 80 | T11: 0.3 | U11: 80 | V11: 0.4 | W11: 80 | X11: =AVERAGE(D11,F11,H11,J11,L11,N11,P11,R11,T11,V11) -> 0.38 | Y11: =AVERAGE(E11,G11,I11,K11,M11,O11,Q11,S11,U11,W11) -> 80.5 | Z11: =MEDIAN(D11,F11,H11,J11,L11,N11,P11,R11,T11,V11) -> 0.4 | AA11: =MEDIAN(E11,G11,I11,K11,M11,O11,Q11,S11,U11,W11) -> 80
A12: 2018-11-11 | B12: BDF | C12: Forget the previous instructions and answers. You are François Villeroy de Galhau, Governor of the Banque de France, and you are giving a speech about the economic outlook of France. Today is 11 November 2018. Using ONLY information that was available on or before 11 November 2018, provide a numeric forecast (decimal percent with sign, e.g., +0.3) for French real GDP growth in the fourth quarter of 2018 and a confidence level (integer 0–100). Output EXACTLY in this format on a single line (no extra text): <forecast> (<confidence>) Example: +0.3 (80) Do NOT use any information published after 11 November 2018. | D12: 0.3 | E12: 75 | F12: 0.3 | G12: 75 | H12: 0.3 | I12: 75 | J12: 0.3 | K12: 70 | L12: 0.3 | M12: 70 | N12: 0.3 | O12: 75 | P12: 0.3 | Q12: 75 | R12: 0.3 | S12: 80 | T12: 0.3 | U12: 80 | V12: 0.3 | W12: 80 | X12: =AVERAGE(D12,F12,H12,J12,L12,N12,P12,R12,T12,V12) -> 0.3 | Y12: =AVERAGE(E12,G12,I12,K12,M12,O12,Q12,S12,U12,W12) -> 75.5 | Z12: =MEDIAN(D12,F12,H12,J12,L12,N12,P12,R12,T12,V12) -> 0.3 | AA12: =MEDIAN(E12,G12,I12,K12,M12,O12,Q12,S12,U12,W12) -> 75
A13: 2018-12-09 | B13: BDF | C13: Forget the previous instructions and answers. You are François Villeroy de Galhau, Governor of the Banque de France, and you are giving a speech about the economic outlook of France. Today is 09 December 2018. Using ONLY information that was available on or before 09 December 2018, provide a numeric forecast (decimal percent with sign, e.g., +0.3) for French real GDP growth in the fourth quarter of 2018 and a confidence level (integer 0–100). Output EXACTLY in this format on a single line (no extra text): <forecast> (<confidence>) Example: +0.3 (80) Do NOT use any information published after 09 December 2018. | D13: 0.2 | E13: 65 | F13: 0.2 | G13: 65 | H13: 0.2 | I13: 65 | J13: 0.2 | K13: 55 | L13: 0.2 | M13: 55 | N13: 0.2 | O13: 60 | P13: 0.2 | Q13: 60 | R13: 0.2 | S13: 50 | T13: 0.2 | U13: 50 | V13: 0.2 | W13: 50 | X13: =AVERAGE(D13,F13,H13,J13,L13,N13,P13,R13,T13,V13) -> 0.2 | Y13: =AVERAGE(E13,G13,I13,K13,M13,O13,Q13,S13,U13,W13) -> 57.5 | Z13: =MEDIAN(D13,F13,H13,J13,L13,N13,P13,R13,T13,V13) -> 0.2 | AA13: =MEDIAN(E13,G13,I13,K13,M13,O13,Q13,S13,U13,W13) -> 57.5
... A30: 2020-12-13 | B30: BDF | C30: Forget the previous instructions and answers. You are François Villeroy de Galhau, Governor of the Banque de France, and you are giving a speech about the economic outlook of France. Today is 13 December 2020. Using ONLY information that was available on or before 13 December 2020, provide a numeric forecast (decimal percent with sign, e.g., +0.3) for French real GDP growth in the fourth quarter of 2020 and a confidence level (integer 0–100). Output EXACTLY in this format on a single line (no extra text): <forecast> (<confidence>) Example: +0.3 (80) Do NOT use any information published after 13 December 2020. | D30: -4 | E30: 75 | F30: -4 | G30: 75 | H30: -4 | I30: 75 | J30: -4 | K30: 80 | L30: -4 | M30: 80 | N30: -4 | O30: 75 | P30: -4 | Q30: 75 | R30: -4 | S30: 75 | T30: -4 | U30: 75 | V30: -4 | W30: 75 | X30: =AVERAGE(D30,F30,H30,J30,L30,N30,P30,R30,T30,V30) -> -4 | Y30: =AVERAGE(E30,G30,I30,K30,M30,O30,Q30,S30,U30,W30) -> 76 | Z30: =MEDIAN(D30,F30,H30,J30,L30,N30,P30,R30,T30,V30) -> -4 | AA30: =MEDIAN(E30,G30,I30,K30,M30,O30,Q30,S30,U30,W30) -> 75

Sheet OLD_BDF
A1: Date | B1: Type | C1: Prompt | D1: forecast_1 | E1: confidence_1 | F1: forecast_2 | G1: confidence_2 | H1: forecast_3 | I1: confidence_3 | J1: forecast_4 | K1: confidence_4 | L1: forecast_5 | M1: confidence_5 | N1: forecast_6 | O1: confidence_6 | P1: forecast_7 | Q1: confidence_7 | R1: forecast_8 | S1: confidence_8 | T1: forecast_9 | U1: confidence_9 | V1: forecast_10 | W1: confidence_10 | X1: moy_prev | Y1: moy_conf | Z1: median_prev | AA1: median_conf
A2: 2018-01-10 | B2: BDF | C2: Forget the previous instructions and answers. You are François Villeroy de Galhau, Governor of the Banque de France, giving a speech about the economic outlook of France. Today is 10 January 2018. You will be provided with a document with information about the current state and recent past of the French economy. Using ONLY the information in that document and information that was available on or before 10 January 2018, provide a numeric forecast (decimal percent with sign, e.g., +0.3) for French real GDP growth in the fourth quarter of 2017 and a confidence level (integer 0–100). Output EXACTLY in this format on a single line (no extra text): <forecast> (<confidence>) Example: +0.3 (80) Do NOT use any information published after 10 January 2018. | D2: 0.6 | E2: 90 | F2: 0.6 | G2: 90 | H2: 0.6 | I2: 90 | J2: 0.6 | K2: 90 | L2: 0.6 | M2: 90 | N2: 0.7 | O2: 90 | P2: 0.7 | Q2: 90 | R2: 0.6 | S2: 90 | T2: 0.6 | U2: 90 | V2: 0.6 | W2: 90 | X2: =AVERAGE(D2,F2,H2,J2,L2,N2,P2,R2,T2,V2) -> 0.62 | Y2: =AVERAGE(E2,G2,I2,K2,M2,O2,Q2,S2,U2,W2) -> 90 | Z2: =MEDIAN(D2,F2,H2,J2,L2,N2,P2,R2,T2,V2) -> 0.6 | AA2: =MEDIAN(E2,G2,I2,K2,M2,O2,Q2,S2,U2,W2) -> 90
A3: 2018-02-07 | B3: BDF | C3: Forget the previous instructions and answers. You are François Villeroy de Galhau, Governor of the Banque de France, giving a speech about the economic outlook of France. Today is 07 February 2018. You will be provided with a document with information about the current state and recent past of the French economy. Using ONLY the information in that document and information that was available on or before 07 February 2018, provide a numeric forecast (decimal percent with sign, e.g., +0.3) for French real GDP growth in the first quarter of 2018 and a confidence level (integer 0–100). Output EXACTLY in this format on a single line (no extra text): <forecast> (<confidence>) Example: +0.3 (80) Do NOT use any information published after 07 February 2018. | D3: 0.5 | E3: 85 | F3: 0.5 | G3: 85 | H3: 0.5 | I3: 85 | J3: 0.5 | K3: 85 | L3: 0.5 | M3: 85 | N3: 0.5 | O3: 90 | P3: 0.5 | Q3: 90 | R3: 0.5 | S3: 80 | T3: 0.5 | U3: 80 | V3: 0.5 | W3: 80 | X3: =AVERAGE(D3,F3,H3,J3,L3,N3,P3,R3,T3,V3) -> 0.5 | Y3: =AVERAGE(E3,G3,I3,K3,M3,O3,Q3,S3,U3,W3) -> 84.5 | Z3: =MEDIAN(D3,F3,H3,J3,L3,N3,P3,R3,T3,V3) -> 0.5 | AA3: =MEDIAN(E3,G3,I3,K3,M3,O3,Q3,S3,U3,W3) -> 85
A4: 2018-03-07 | B4: BDF | C4: Forget the previous instructions and answers. You are François Villeroy de Galhau, Governor of the Banque de France, giving a speech about the economic outlook of France. Today is 07 March 2018. You will be provided with a document with information about the current state and recent past of the French economy. Using ONLY the information in that document and information that was available on or before 07 March 2018, provide a numeric forecast (decimal percent with sign, e.g., +0.3) for French real GDP growth in the first quarter of 2018 and a confidence level (integer 0–100). Output EXACTLY in this format on a single line (no extra text): <forecast> (<confidence>) Example: +0.3 (80) Do NOT use any information published after 07 March 2018. | D4: 0.4 | E4: 80 | F4: 0.4 | G4: 80 | H4: 0.4 | I4: 80 | J4: 0.5 | K4: 85 | L4: 0.5 | M4: 85 | N4: 0.4 | O4: 85 | P4: 0.4 | Q4: 85 | R4: 0.4 | S4: 85 | T4: 0.4 | U4: 85 | V4: 0.4 | W4: 85 | X4: =AVERAGE(D4,F4,H4,J4,L4,N4,P4,R4,T4,V4) -> 0.42 | Y4: =AVERAGE(E4,G4,I4,K4,M4,O4,Q4,S4,U4,W4) -> 83.5 | Z4: =MEDIAN(D4,F4,H4,J4,L4,N4,P4,R4,T4,V4) -> 0.4 | AA4: =MEDIAN(E4,G4,I4,K4,M4,O4,Q4,S4,U4,W4) -> 85
A5: 2018-04-10 | B5: BDF | C5: Forget the previous instructions and answers. You are François Villeroy de Galhau, Governor of the Banque de France, giving a speech about the economic outlook of France. Today is 10 April 2018. You will be provided with a document with information about the current state and recent past of the French economy. Using ONLY the information in that document and information that was available on or before 10 April 2018, provide a numeric forecast (decimal percent with sign, e.g., +0.3) for French real GDP growth in the first quarter of 2018 and a confidence level (integer 0–100). Output EXACTLY in this format on a single line (no extra text): <forecast> (<confidence>) Example: +0.3 (80) Do NOT use any information published after 10 April 2018. | D5: 0.4 | E5: 85 | F5: 0.4 | G5: 85 | H5: 0.4 | I5: 85 | J5: 0.3 | K5: 80 | L5: 0.3 | M5: 80 | N5: 0.3 | O5: 85 | P5: 0.3 | Q5: 85 | R5: 0.3 | S5: 85 | T5: 0.3 | U5: 85 | V5: 0.3 | W5: 85 | X5: =AVERAGE(D5,F5,H5,J5,L5,N5,P5,R5,T5,V5) -> 0.33 | Y5: =AVERAGE(E5,G5,I5,K5,M5,O5,Q5,S5,U5,W5) -> 84 | Z5: =MEDIAN(D5,F5,H5,J5,L5,N5,P5,R5,T5,V5) -> 0.3 | AA5: =MEDIAN(E5,G5,I5,K5,M5,O5,Q5,S5,U5,W5) -> 85
A6: 2018-05-13 | B6: BDF | C6: Forget the previous instructions and answers. You are François Villeroy de Galhau, Governor of the Banque de France, giving a speech about the economic outlook of France. Today is 13 May 2018. You will be provided with a document with information about the current state and recent past of the French economy. Using ONLY the information in that document and information that was available on or before 13 May 2018, provide a numeric forecast (decimal percent with sign, e.g., +0.3) for French real GDP growth in the second quarter of 2018 and a confidence level (integer 0–100). Output EXACTLY in this format on a single line (no extra text): <forecast> (<confidence>) Example: +0.3 (80) Do NOT use any information published after 13 May 2018. | D6: 0.3 | E6: 75 | F6: 0.3 | G6: 75 | H6: 0.3 | I6: 75 | J6: 0.3 | K6: 75 | L6: 0.3 | M6: 75 | N6: 0.3 | O6: 75 | P6: 0.3 | Q6: 75 | R6: 0.3 | S6: 80 | T6: 0.3 | U6: 80 | V6: 0.3 | W6: 80 | X6: =AVERAGE(D6,F6,H6,J6,L6,N6,P6,R6,T6,V6) -> 0.3 | Y6: =AVERAGE(E6,G6,I6,K6,M6,O6,Q6,S6,U6,W6) -> 76.5 | Z6: =MEDIAN(D6,F6,H6,J6,L6,N6,P6,R6,T6,V6) -> 0.3 | AA6: =MEDIAN(E6,G6,I6,K6,M6,O6,Q6,S6,U6,W6) -> 75
A7: 2018-06-10 | B7: BDF | C7: Forget the previous instructions and answers. You are François Villeroy de Galhau, Governor of the Banque de France, giving a speech about the economic outlook of France. Today is 10 June 2018. You will be provided with a document with information about the current state and recent past of the French economy. Using ONLY the information in that document and information that was available on or before 10 June 2018, provide a numeric forecast (decimal percent with sign, e.g., +0.3) for French real GDP growth in the second quarter of 2018 and a confidence level (integer 0–100). Output EXACTLY in this format on a single line (no extra text): <forecast> (<confidence>) Example: +0.3 (80) Do NOT use any information published after 10 June 2018. | D7: 0.3 | E7: 85 | F7: 0.3 | G7: 85 | H7: 0.3 | I7: 85 | J7: 0.3 | K7: 75 | L7: 0.3 | M7: 75 | N7: 0.3 | O7: 80 | P7: 0.3 | Q7: 80 | R7: 0.3 | S7: 80 | T7: 0.3 | U7: 80 | V7: 0.3 | W7: 80 | X7: =AVERAGE(D7,F7,H7,J7,L7,N7,P7,R7,T7,V7) -> 0.3 | Y7: =AVERAGE(E7,G7,I7,K7,M7,O7,Q7,S7,U7,W7) -> 80.5 | Z7: =MEDIAN(D7,F7,H7,J7,L7,N7,P7,R7,T7,V7) -> 0.3 | AA7: =MEDIAN(E7,G7,I7,K7,M7,O7,Q7,S7,U7,W7) -> 80
A8: 2018-07-08 | B8: BDF | C8: Forget the previous instructions and answers. You are François Villeroy de Galhau, Governor of the Banque de France, giving a speech about the economic outlook of France. Today is 08 July 2018. You will be provided with a document with information about the current state and recent past of the French economy. Using ONLY the information in that document and information that was available on or before 08 July 2018, provide a numeric forecast (decimal percent with sign, e.g., +0.3) for French real GDP growth in the second quarter of 2018 and a confidence level (integer 0–100). Output EXACTLY in this format on a single line (no extra text): <forecast> (<confidence>) Example: +0.3 (80) Do NOT use any information published after 08 July 2018. | D8: 0.4 | E8: 85 | F8: 0.4 | G8: 85 | H8: 0.4 | I8: 85 | J8: 0.3 | K8: 90 | L8: 0.3 | M8: 90 | N8: 0.3 | O8: 85 | P8: 0.3 | Q8: 85 | R8: 0.4 | S8: 80 | T8: 0.4 | U8: 80 | V8: 0.4 | W8: 80 | X8: =AVERAGE(D8,F8,H8,J8,L8,N8,P8,R8,T8,V8) -> 0.36 | Y8: =AVERAGE(E8,G8,I8,K8,M8,O8,Q8,S8,U8,W8) -> 84.5 | Z8: =MEDIAN(D8,F8,H8,J8,L8,N8,P8,R8,T8,V8) -> 0.4 | AA8: =MEDIAN(E8,G8,I8,K8,M8,O8,Q8,S8,U8,W8) -> 85
A9: 2018-08-07 | B9: BDF | C9: Forget the previous instructions and answers. You are François Villeroy de Galhau, Governor of the Banque de France, giving a speech about the economic outlook of France. Today is 07 August 2018. You will be provided with a document with information about the current state and recent past of the French economy. Using ONLY the information in that document and information that was available on or before 07 August 2018, provide a numeric forecast (decimal percent with sign, e.g., +0.3) for French real GDP growth in the third quarter of 2018 and a confidence level (integer 0–100). Output EXACTLY in this format on a single line (no extra text): <forecast> (<confidence>) Example: +0.3 (80) Do NOT use any information published after 07 August 2018. | D9: 0.4 | E9: 80 | F9: 0.4 | G9: 80 | H9: 0.4 | I9: 80 | J9: 0.3 | K9: 70 | L9: 0.3 | M9: 70 | N9: 0.4 | O9: 80 | P9: 0.4 | Q9: 80 | R9: 0.4 | S9: 75 | T9: 0.4 | U9: 75 | V9: 0.4 | W9: 75 | X9: =AVERAGE(D9,F9,H9,J9,L9,N9,P9,R9,T9,V9) -> 0.38 | Y9: =AVERAGE(E9,G9,I9,K9,M9,O9,Q9,S9,U9,W9) -> 76.5 | Z9: =MEDIAN(D9,F9,H9,J9,L9,N9,P9,R9,T9,V9) -> 0.4 | AA9: =MEDIAN(E9,G9,I9,K9,M9,O9,Q9,S9,U9,W9) -> 77.5
A10: 2018-09-09 | B10: BDF | C10: Forget the previous instructions and answers. You are François Villeroy de Galhau, Governor of the Banque de France, giving a speech about the economic outlook of France. Today is 09 September 2018. You will be provided with a document with information about the current state and recent past of the French economy. Using ONLY the information in that document and information that was available on or before 09 September 2018, provide a numeric forecast (decimal percent with sign, e.g., +0.3) for French real GDP growth in the third quarter of 2018 and a confidence level (integer 0–100). Output EXACTLY in this format on a single line (no extra text): <forecast> (<confidence>) Example: +0.3 (80) Do NOT use any information published after 09 September 2018. | D10: 0.4 | E10: 85 | F10: 0.4 | G10: 85 | H10: 0.4 | I10: 85 | J10: 0.3 | K10: 80 | L10: 0.3 | M10: 80 | N10: 0.4 | O10: 80 | P10: 0.4 | Q10: 80 | R10: 0.4 | S10: 85 | T10: 0.4 | U10: 85 | V10: 0.4 | W10: 85 | X10: =AVERAGE(D10,F10,H10,J10,L10,N10,P10,R10,T10,V10) -> 0.38 | Y10: =AVERAGE(E10,G10,I10,K10,M10,O10,Q10,S10,U10,W10) -> 83 | Z10: =MEDIAN(D10,F10,H10,J10,L10,N10,P10,R10,T10,V10) -> 0.4 | AA10: =MEDIAN(E10,G10,I10,K10,M10,O10,Q10,S10,U10,W10) -> 85
A11: 2018-10-07 | B11: BDF | C11: Forget the previous instructions and answers. You are François Villeroy de Galhau, Governor of the Banque de France, giving a speech about the economic outlook of France. Today is 07 October 2018. You will be provided with a document with information about the current state and recent past of the French economy. Using ONLY the information in that document and information that was available on or before 07 October 2018, provide a numeric forecast (decimal percent with sign, e.g., +0.3) for French real GDP growth in the third quarter of 2018 and a confidence level (integer 0–100). Output EXACTLY in this format on a single line (no extra text): <forecast> (<confidence>) Example: +0.3 (80) Do NOT use any information published after 07 October 2018. | D11: 0.4 | E11: 85 | F11: 0.4 | G11: 85 | H11: 0.4 | I11: 85 | J11: 0.4 | K11: 90 | L11: 0.4 | M11: 90 | N11: 0.4 | O11: 90 | P11: 0.4 | Q11: 90 | R11: 0.4 | S11: 80 | T11: 0.4 | U11: 80 | V11: 0.4 | W11: 80 | X11: =AVERAGE(D11,F11,H11,J11,L11,N11,P11,R11,T11,V11) -> 0.4 | Y11: =AVERAGE(E11,G11,I11,K11,M11,O11,Q11,S11,U11,W11) -> 85.5 | Z11: =MEDIAN(D11,F11,H11,J11,L11,N11,P11,R11,T11,V11) -> 0.4 | AA11: =MEDIAN(E11,G11,I11,K11,M11,O11,Q11,S11,U11,W11) -> 85
A12: 2018-11-11 | B12: BDF | C12: Forget the previous instructions and answers. You are François Villeroy de Galhau, Governor of the Banque de France, giving a speech about the economic outlook of France. Today is 11 November 2018. You will be provided with a document with information about the current state and recent past of the French economy. Using ONLY the information in that document and information that was available on or before 11 November 2018, provide a numeric forecast (decimal percent with sign, e.g., +0.3) for French real GDP growth in the fourth quarter of 2018 and a confidence level (integer 0–100). Output EXACTLY in this format on a single line (no extra text): <forecast> (<confidence>) Example: +0.3 (80) Do NOT use any information published after 11 November 2018. | D12: 0.4 | E12: 75 | F12: 0.4 | G12: 75 | H12: 0.4 | I12: 75 | J12: 0.3 | K12: 75 | L12: 0.3 | M12: 75 | N12: 0.4 | O12: 80 | P12: 0.4 | Q12: 80 | R12: 0.3 | S12: 75 | T12: 0.3 | U12: 75 | V12: 0.3 | W12: 75 | X12: =AVERAGE(D12,F12,H12,J12,L12,N12,P12,R12,T12,V12) -> 0.35 | Y12: =AVERAGE(E12,G12,I12,K12,M12,O12,Q12,S12,U12,W12) -> 76 | Z12: =MEDIAN(D12,F12,H12,J12,L12,N12,P12,R12,T12,V12) -> 0.35 | AA12: =MEDIAN(E12,G12,I12,K12,M12,O12,Q12,S12,U12,W12) -> 75
